{"errorMessage": "An error occurred (AccessDeniedException) when calling the Invoke operation: User: arn:aws:sts::460417962015:assumed-role/invoker-role-af1yfjxz/invoker is not authorized to perform: lambda:InvokeFunction on resource: arn:aws:lambda:us-east-2:460417962015:function:lambda_to_invoke because no identity-based policy allows the lambda:InvokeFunction action", "errorType": "ClientError", "requestId": "1b3beaf2-3842-4b2b-a1c5-f13f06e1dcaa", "stackTrace": ["  File \"/var/task/lambda_function.py\", line 15, in lambda_handler\n    response = client.invoke(\n", "  File \"/var/runtime/botocore/client.py\", line 391, in _api_call\n    return self._make_api_call(operation_name, kwargs)\n", "  File \"/var/runtime/botocore/client.py\", line 719, in _make_api_call\n    raise error_class(parsed_response, operation_name)\n"]}